<?xml version="1.0"?>
<sdf version="1.8">
  <model name="spot">
    <link name="base_link">
      <inertial>
        <pose>0.005937 0.000326 0.04636 0 -0 0</pose>
        <!-- <mass>20.492</mass> -->
        <mass>2</mass>

        <inertia>
          <ixx>0.287877</ixx>
          <ixy>0.0014834</ixy>
          <ixz>-0.0347842</ixz>
          <iyy>1.31868</iyy>
          <iyz>-0.000519074</iyz>
          <izz>1.18915</izz>
        </inertia>
      </inertial>
      <collision name="base_link_collision">
        <geometry>
          <mesh>
            <uri>package://spot_description/models/spot/meshes/body_collision.stl</uri>
          </mesh>
        </geometry>
      </collision>
      <visual name="base_link_visual">
        <geometry>
          <mesh>
            <uri>package://spot_description/models/spot/meshes/body.dae</uri>
          </mesh>
        </geometry>
      </visual>
      <self_collide>0</self_collide>
    </link>
    <link name="body">
      <inertial>
        <mass>1e-05</mass>
        <inertia>
          <ixx>0.001</ixx>
          <ixy>1e-06</ixy>
          <ixz>1e-06</ixz>
          <iyy>0.001</iyy>
          <iyz>1e-06</iyz>
          <izz>0.001</izz>
        </inertia>
      </inertial>
    </link>
    <joint name="base_link_joint" type="fixed">
      <child>body</child>
      <parent>base_link</parent>
      <axis>
        <dynamics>
          <spring_reference>0</spring_reference>
          <spring_stiffness>0</spring_stiffness>
        </dynamics>
        <xyz>0 0 1</xyz>
        <limit>
          <lower>-1e+16</lower>
          <upper>1e+16</upper>
        </limit>
      </axis>
      <physics>
        <ode>
          <limit>
            <cfm>0</cfm>
            <erp>0.2</erp>
          </limit>
        </ode>
      </physics>
    </joint>
    <link name="front_rail">
      <pose>0.223 0 0.0805 0 -0 0</pose>
      <inertial>
        <mass>1e-05</mass>
        <inertia>
          <ixx>0.001</ixx>
          <ixy>1e-06</ixy>
          <ixz>1e-06</ixz>
          <iyy>0.001</iyy>
          <iyz>1e-06</iyz>
          <izz>0.001</izz>
        </inertia>
      </inertial>
    </link>

    

   
   

    <joint name="front_rail_joint" type="fixed">
      <child>front_rail</child>
      <parent>body</parent>
      <axis>
        <dynamics>
          <spring_reference>0</spring_reference>
          <spring_stiffness>0</spring_stiffness>
        </dynamics>
        <xyz>0 0 1</xyz>
        <limit>
          <lower>-1e+16</lower>
          <upper>1e+16</upper>
        </limit>
      </axis>
      <physics>
        <ode>
          <limit>
            <cfm>0</cfm>
            <erp>0.2</erp>
          </limit>
        </ode>
      </physics>
    </joint>
    <link name="rear_rail">
      <pose>-0.223 0 0.0805 0 -0 0</pose>
      <inertial>
        <mass>1e-05</mass>
        <inertia>
          <ixx>0.001</ixx>
          <ixy>1e-06</ixy>
          <ixz>1e-06</ixz>
          <iyy>0.001</iyy>
          <iyz>1e-06</iyz>
          <izz>0.001</izz>
        </inertia>
      </inertial>
    </link>

    <joint name="rear_rail_joint" type="fixed">
      <child>rear_rail</child>
      <parent>body</parent>
      <axis>
        <dynamics>
          <spring_reference>0</spring_reference>
          <spring_stiffness>0</spring_stiffness>
        </dynamics>
        <xyz>0 0 1</xyz>
        <limit>
          <lower>-1e+16</lower>
          <upper>1e+16</upper>
        </limit>
      </axis>
      <physics>
        <ode>
          <limit>
            <cfm>0</cfm>
            <erp>0.2</erp>
          </limit>
        </ode>
      </physics>
    </joint>
    <link name="battery">
      <pose>0 0 -0.03 0 -0 0</pose>
      <inertial>
        <mass>4</mass>
        <inertia>
          <ixx>0.012291</ixx>
          <ixy>0</ixy>
          <ixz>0</ixz>
          <iyy>0.037875</iyy>
          <iyz>0</iyz>
          <izz>0.0444</izz>
        </inertia>
      </inertial>
      <collision name="battery_collision">
        <geometry>
          <box>
            <size>0.324 0.168 0.093</size>
          </box>
        </geometry>
      </collision>
      <visual name="battery_visual">
        <geometry>
          <box>
            <size>0.324 0.168 0.093</size>
          </box>
        </geometry>
        <material>
          <ambient>0.917647 0.654902 0 1</ambient>
          <diffuse>0.917647 0.654902 0 1</diffuse>
          <specular>0.917647 0.654902 0 1</specular>
          <emissive>0 0 0 0</emissive>
        </material>
      </visual>
    </link>
    <joint name="battery_joint" type="fixed">
      <child>battery</child>
      <parent>base_link</parent>
      <axis>
        <dynamics>
          <spring_reference>0</spring_reference>
          <spring_stiffness>0</spring_stiffness>
        </dynamics>
        <xyz>0 0 1</xyz>
        <limit>
          <lower>-1e+16</lower>
          <upper>1e+16</upper>
        </limit>
      </axis>
      <physics>
        <ode>
          <limit>
            <cfm>0</cfm>
            <erp>0.2</erp>
          </limit>
        </ode>
      </physics>
    </joint>
   
    <link name="front_left_hip">
      <pose>0.29785 0.055 0 0 -0 0</pose>
      <inertial>
        <mass>2</mass>
        <inertia>
          <ixx>0.0027</ixx>
          <ixy>0</ixy>
          <ixz>0</ixz>
          <iyy>0.00416667</iyy>
          <iyz>0</iyz>
          <izz>0.00416667</izz>
        </inertia>
      </inertial>
      <collision name="front_left_hip_collision">
        <geometry>
          <mesh>
            <uri>package://spot_description/models/spot/meshes/front_left_hip_collision.stl</uri>
          </mesh>
        </geometry>
      </collision>
      <visual name="front_left_hip_visual">
        <geometry>
          <mesh>
            <uri>package://spot_description/models/spot/meshes/front_left_hip.dae</uri>
          </mesh>
        </geometry>
      </visual>
    </link>

    <joint name="front_left_hip_x" type="revolute">
      <child>front_left_hip</child>
      <parent>base_link</parent>
      <axis>
        <xyz>1 0 0</xyz>
        <limit>
          <lower>-0.785398</lower>
          <upper>0.785398</upper>
          <effort>80</effort>
          <velocity>15</velocity>
        </limit>
        <dynamics>
          <spring_reference>0</spring_reference>
          <spring_stiffness>0</spring_stiffness>
        </dynamics>
      </axis>
    </joint>
    <link name="front_left_upper_leg">
      <pose>0.29785 0.165945 0 0 -0 0</pose>
      <inertial>
        <pose>0 0 -0.14 0 -0 0</pose>
        <mass>1</mass>
        <inertia>
          <ixx>0.0155334</ixx>
          <ixy>0</ixy>
          <ixz>0</ixz>
          <iyy>0.0155334</iyy>
          <iyz>0</iyz>
          <izz>0.000962667</izz>
        </inertia>
      </inertial>
      <collision name="front_left_upper_leg_collision">
        <geometry>
          <mesh>
            <uri>package://spot_description/models/spot/meshes/front_left_upper_leg_collision.stl</uri>
          </mesh>
        </geometry>
      </collision>
      <visual name="front_left_upper_leg_visual">
        <geometry>
          <mesh>
            <uri>package://spot_description/models/spot/meshes/front_left_upper_leg.dae</uri>
          </mesh>
        </geometry>
      </visual>
    </link>
    <joint name="front_left_hip_y" type="revolute">
      <child>front_left_upper_leg</child>
      <parent>front_left_hip</parent>
      <axis>
        <xyz>0 1 0</xyz>
        <limit>
          <lower>-0.898845</lower>
          <upper>2.29511</upper>
          <effort>80</effort>
          <velocity>15</velocity>
        </limit>
        <dynamics>
          <spring_reference>0</spring_reference>
          <spring_stiffness>0</spring_stiffness>
        </dynamics>
      </axis>
    </joint>
    <link name="front_left_lower_leg">
      <pose>0.32285 0.165945 -0.3205 0 -0 0</pose>
      <inertial>
        <pose>0 0 -0.16 0 -0 0</pose>
        <mass>0.5</mass>
        <inertia>
          <ixx>0.00743438Source Control</ixx>
          <ixy>0</ixy>
          <ixz>0</ixz>
          <iyy>0.00740104</iyy>
          <iyz>0</iyz>
          <izz>0.000135417</izz>
        </inertia>
      </inertial>
      <collision name="front_left_lower_leg_collision">
        <geometry>
          <mesh>
            <scale>0.82 0.97 0.98</scale>
            <uri>package://spot_description/models/spot/meshes/front_left_lower_leg_collision.stl</uri>
          </mesh>
        </geometry>
        <surface>
          <contact>
            <ode>
              <kp>1e+07</kp>
              <kd>100</kd>
            </ode>
          </contact>
          <friction>
            <ode>
              <mu>0.8</mu>
              <mu2>0.8</mu2>
            </ode>
          </friction>
        </surface>
      </collision>
      <collision name="front_left_lower_leg_collision_1">
        <pose>0 0 -0.333 0 -0 0</pose>
        <geometry>
          <sphere>
            <radius>0.04</radius>
          </sphere>
        </geometry>
        <surface>
          <contact>
            <ode>
              <kp>1e+07</kp>
              <kd>100</kd>
            </ode>
          </contact>
          <friction>
            <ode>
              <mu>0.8</mu>
              <mu2>0.8</mu2>
            </ode>
          </friction>
        </surface>
      </collision>
      <visual name="front_left_lower_leg_visual">
        <geometry>
          <mesh>
            <uri>package://spot_description/models/spot/meshes/front_left_lower_leg.dae</uri>
          </mesh>
        </geometry>
        <material>
        </material>
      </visual>
      <sensor name="contact" type="contact">
        <contact>
          <collision>front_left_lower_leg_collision</collision>
          <collision>front_left_lower_leg_collision_1</collision>
          <topic>__default_topic__</topic>
        </contact>
      </sensor>
    </link>
    <joint name="front_left_knee" type="revolute">
      <child>front_left_lower_leg</child>
      <parent>front_left_upper_leg</parent>
      <axis>
        <xyz>0 1 0</xyz>
        <limit>
          <lower>-2.7929</lower>
          <upper>-0.254801</upper>
          <effort>80</effort>
          <velocity>15</velocity>
        </limit>
        <dynamics>
          <spring_reference>0</spring_reference>
          <spring_stiffness>0</spring_stiffness>
        </dynamics>
      </axis>
    </joint>
    <link name="front_left_ee">
      <pose>0.32285 0.165945 -0.6905 0 -0 0</pose>
      <inertial>
        <mass>1e-05</mass>
        <inertia>
          <ixx>0.001</ixx>
          <ixy>1e-06</ixy>
          <ixz>1e-06</ixz>
          <iyy>0.001</iyy>
          <iyz>1e-06</iyz>
          <izz>0.001</izz>
        </inertia>
      </inertial>
    </link>
    <joint name="front_left_foot" type="fixed">
  
      <child>front_left_ee</child>
      <parent>front_left_lower_leg</parent>
      <axis>
        <dynamics>
          <spring_reference>0</spring_reference>
          <spring_stiffness>0</spring_stiffness>
        </dynamics>
        <xyz>0 0 1</xyz>
        <limit>
          <lower>-1e+16</lower>
          <upper>1e+16</upper>
        </limit>
      </axis>
      <physics>
        <ode>
          <limit>
            <cfm>0</cfm>
            <erp>0.2</erp>
          </limit>
        </ode>
      </physics>
    </joint>
    <link name="front_right_hip">
      <pose>0.29785 -0.055 0 0 -0 0</pose>
      <inertial>
        <mass>2</mass>
        <inertia>
          <ixx>0.0027</ixx>
          <ixy>0</ixy>
          <ixz>0</ixz>
          <iyy>0.00416667</iyy>
          <iyz>0</iyz>
          <izz>0.00416667</izz>
        </inertia>
      </inertial>
      <collision name="front_right_hip_collision">
        <geometry>
          <mesh>
            <uri>package://spot_description/models/spot/meshes/front_right_hip_collision.stl</uri>
          </mesh>
        </geometry>
      </collision>
      <visual name="front_right_hip_visual">
        <geometry>
          <mesh>
            <uri>package://spot_description/models/spot/meshes/front_right_hip.dae</uri>
          </mesh>
        </geometry>
      </visual>
    </link>
    <joint name="front_right_hip_x" type="revolute">
      <child>front_right_hip</child>
      <parent>base_link</parent>
      <axis>
        <xyz>1 0 0</xyz>
        <limit>
          <lower>-0.785398</lower>
          <upper>0.785398</upper>
          <effort>80</effort>
          <velocity>15</velocity>
        </limit>
        <dynamics>
          <spring_reference>0</spring_reference>
          <spring_stiffness>0</spring_stiffness>
        </dynamics>
      </axis>
    </joint>
    <link name="front_right_upper_leg">
      <pose>0.29785 -0.165945 0 0 -0 0</pose>
      <inertial>
        <pose>0 0 -0.14 0 -0 0</pose>
        <mass>1</mass>
        <inertia>
          <ixx>0.0155334</ixx>
          <ixy>0</ixy>
          <ixz>0</ixz>
          <iyy>0.0155334</iyy>
          <iyz>0</iyz>
          <izz>0.000962667</izz>
        </inertia>
      </inertial>
      <collision name="front_right_upper_leg_collision">
        <geometry>
          <mesh>
            <uri>package://spot_description/models/spot/meshes/front_right_upper_leg_collision.stl</uri>
          </mesh>
        </geometry>
      </collision>
      <visual name="front_right_upper_leg_visual">
        <geometry>
          <mesh>
            <uri>package://spot_description/models/spot/meshes/front_right_upper_leg.dae</uri>
          </mesh>
        </geometry>
      </visual>
    </link>
    <joint name="front_right_hip_y" type="revolute">
      <child>front_right_upper_leg</child>
      <parent>front_right_hip</parent>
      <axis>
        <xyz>0 1 0</xyz>
        <limit>
          <lower>-0.898845</lower>
          <upper>2.29511</upper>
          <effort>80</effort>
          <velocity>15</velocity>
        </limit>
        <dynamics>
          <spring_reference>0</spring_reference>
          <spring_stiffness>0</spring_stiffness>
        </dynamics>
      </axis>
    </joint>
    <link name="front_right_lower_leg">
      <pose>0.32285 -0.165945 -0.3205 0 -0 0</pose>
      <inertial>
        <pose>0 0 -0.16 0 -0 0</pose>
        <mass>0.5</mass>
        <inertia>
          <ixx>0.00743438</ixx>
          <ixy>0</ixy>
          <ixz>0</ixz>
          <iyy>0.00740104</iyy>
          <iyz>0</iyz>
          <izz>0.000135417</izz>
        </inertia>
      </inertial>
      <collision name="front_right_lower_leg_collision">
        <geometry>
          <mesh>
            <scale>0.82 0.97 0.98</scale>
            <uri>package://spot_description/models/spot/meshes/front_right_lower_leg_collision.stl</uri>
          </mesh>
        </geometry>
        <surface>
          <contact>
            <ode>
              <kp>1e+07</kp>
              <kd>100</kd>
            </ode>
          </contact>
          <friction>
            <ode>
              <mu>0.8</mu>
              <mu2>0.8</mu2>
            </ode>
          </friction>
        </surface>
      </collision>
      <collision name="front_right_lower_leg_collision_1">
        <pose>0 0 -0.333 0 -0 0</pose>
        <geometry>
          <sphere>
            <radius>0.04</radius>
          </sphere>
        </geometry>
        <surface>
          <contact>
            <ode>
              <kp>1e+07</kp>
              <kd>100</kd>
            </ode>
          </contact>
          <friction>
            <ode>
              <mu>0.8</mu>
              <mu2>0.8</mu2>
            </ode>
          </friction>
        </surface>
      </collision>
      <visual name="front_right_lower_leg_visual">
        <geometry>
          <mesh>
            <uri>package://spot_description/models/spot/meshes/front_right_lower_leg.dae</uri>
          </mesh>
        </geometry>
        <material>
        </material>
      </visual>
      <sensor name="contact" type="contact">
        <contact>
          <collision>front_right_lower_leg_collision</collision>
          <collision>front_right_lower_leg_collision_1</collision>
          <topic>__default_topic__</topic>
        </contact>
      </sensor>
    </link>
    <joint name="front_right_knee" type="revolute">
      <child>front_right_lower_leg</child>
      <parent>front_right_upper_leg</parent>
      <axis>
        <xyz>0 1 0</xyz>
        <limit>
          <lower>-2.7929</lower>
          <upper>-0.254801</upper>
          <effort>80</effort>
          <velocity>15</velocity>
        </limit>
        <dynamics>
          <spring_reference>0</spring_reference>
          <spring_stiffness>0</spring_stiffness>
        </dynamics>
      </axis>
    </joint>
    <link name="front_right_ee">
      <pose>0.32285 -0.165945 -0.6905 0 -0 0</pose>
      <inertial>
        <mass>1e-05</mass>
        <inertia>
          <ixx>0.001</ixx>
          <ixy>1e-06</ixy>
          <ixz>1e-06</ixz>
          <iyy>0.001</iyy>
          <iyz>1e-06</iyz>
          <izz>0.001</izz>
        </inertia>
      </inertial>
    </link>
    <joint name="front_right_foot" type="fixed">
      <child>front_right_ee</child>
      <parent>front_right_lower_leg</parent>
      <axis>
        <dynamics>
          <spring_reference>0</spring_reference>
          <spring_stiffness>0</spring_stiffness>
        </dynamics>
        <xyz>0 0 1</xyz>
        <limit>
          <lower>-1e+16</lower>
          <upper>1e+16</upper>
        </limit>
      </axis>
      <physics>
        <ode>
          <limit>
            <cfm>0</cfm>
            <erp>0.2</erp>
          </limit>
        </ode>
      </physics>
    </joint>
    <link name="imu">
      <inertial>
        <mass>1e-05</mass>
        <inertia>
          <ixx>0.001</ixx>
          <ixy>1e-06</ixy>
          <ixz>1e-06</ixz>
          <iyy>0.001</iyy>
          <iyz>1e-06</iyz>
          <izz>0.001</izz>
        </inertia>
      </inertial>
      <sensor name="imu" type="imu">
        <always_on>1</always_on>
        <update_rate>50</update_rate>
        <topic>model/spot/imu</topic>
        <imu>
          <enable_orientation>0</enable_orientation>
          <angular_velocity>
            <x>
              <noise type="gaussian">
                <mean>0</mean>
                <stddev>0.009</stddev>
                <bias_mean>0.00075</bias_mean>
                <bias_stddev>0.005</bias_stddev>
                <dynamic_bias_stddev>2e-05</dynamic_bias_stddev>
                <dynamic_bias_correlation_time>400</dynamic_bias_correlation_time>
                <precision>0.00025</precision>
              </noise>
            </x>
            <y>
              <noise type="gaussian">
                <mean>0</mean>
                <stddev>0.009</stddev>
                <bias_mean>0.00075</bias_mean>
                <bias_stddev>0.005</bias_stddev>
                <dynamic_bias_stddev>2e-05</dynamic_bias_stddev>
                <dynamic_bias_correlation_time>400</dynamic_bias_correlation_time>
                <precision>0.00025</precision>
              </noise>
            </y>
            <z>
              <noise type="gaussian">
                <mean>0</mean>
                <stddev>0.009</stddev>
                <bias_mean>0.00075</bias_mean>
                <bias_stddev>0.005</bias_stddev>
                <dynamic_bias_stddev>2e-05</dynamic_bias_stddev>
                <dynamic_bias_correlation_time>400</dynamic_bias_correlation_time>
                <precision>0.00025</precision>
              </noise>
            </z>
          </angular_velocity>
          <linear_acceleration>
            <x>
              <noise type="gaussian">
                <mean>0</mean>
                <stddev>0.021</stddev>
                <bias_mean>0.05</bias_mean>
                <bias_stddev>0.0075</bias_stddev>
                <dynamic_bias_stddev>0.000375</dynamic_bias_stddev>
                <dynamic_bias_correlation_time>175</dynamic_bias_correlation_time>
                <precision>0.005</precision>
              </noise>
            </x>
            <y>
              <noise type="gaussian">
                <mean>0</mean>
                <stddev>0.021</stddev>
                <bias_mean>0.05</bias_mean>
                <bias_stddev>0.0075</bias_stddev>
                <dynamic_bias_stddev>0.000375</dynamic_bias_stddev>
                <dynamic_bias_correlation_time>175</dynamic_bias_correlation_time>
                <precision>0.005</precision>
              </noise>
            </y>
            <z>
              <noise type="gaussian">
                <mean>0</mean>
                <stddev>0.021</stddev>
                <bias_mean>0.05</bias_mean>
                <bias_stddev>0.0075</bias_stddev>
                <dynamic_bias_stddev>0.000375</dynamic_bias_stddev>
                <dynamic_bias_correlation_time>175</dynamic_bias_correlation_time>
                <precision>0.005</precision>
              </noise>
            </z>
          </linear_acceleration>
        </imu>
      </sensor>
    </link>
    <joint name="imu_j" type="fixed">
      <child>imu</child>
      <parent>base_link</parent>
      <axis>
        <dynamics>
          <spring_reference>0</spring_reference>
          <spring_stiffness>0</spring_stiffness>
        </dynamics>
        <xyz>0 0 1</xyz>
        <limit>
          <lower>-1e+16</lower>
          <upper>1e+16</upper>
        </limit>
      </axis>
      <physics>
        <ode>
          <limit>
            <cfm>0</cfm>
            <erp>0.2</erp>
          </limit>
        </ode>
      </physics>
    </joint>
    <link name="rear_left_hip">
      <pose>-0.29785 0.055 0 0 -0 0</pose>
      <inertial>
        <mass>2</mass>
        <inertia>
          <ixx>0.0027</ixx>
          <ixy>0</ixy>
          <ixz>0</ixz>
          <iyy>0.00416667</iyy>
          <iyz>0</iyz>
          <izz>0.00416667</izz>
        </inertia>
      </inertial>
      <collision name="rear_left_hip_collision">
        <geometry>
          <mesh>
            <uri>package://spot_description/models/spot/meshes/rear_left_hip_collision.stl</uri>
          </mesh>
        </geometry>
      </collision>
      <visual name="rear_left_hip_visual">
        <geometry>
          <mesh>
            <uri>package://spot_description/models/spot/meshes/rear_left_hip.dae</uri>
          </mesh>
        </geometry>
      </visual>
    </link>
    <joint name="rear_left_hip_x" type="revolute">
      <child>rear_left_hip</child>
      <parent>base_link</parent>
      <axis>
        <xyz>1 0 0</xyz>
        <limit>
          <lower>-0.785398</lower>
          <upper>0.785398</upper>
          <effort>80</effort>
          <velocity>15</velocity>
        </limit>
        <dynamics>
          <spring_reference>0</spring_reference>
          <spring_stiffness>0</spring_stiffness>
        </dynamics>
      </axis>
    </joint>
    <link name="rear_left_upper_leg">
      <pose>-0.29785 0.165945 0 0 -0 0</pose>
      <inertial>
        <pose>0 0 -0.14 0 -0 0</pose>
        <mass>1</mass>
        <inertia>
          <ixx>0.0155334</ixx>
          <ixy>0</ixy>
          <ixz>0</ixz>
          <iyy>0.0155334</iyy>
          <iyz>0</iyz>
          <izz>0.000962667</izz>
        </inertia>
      </inertial>
      <collision name="rear_left_upper_leg_collision">
        <geometry>
          <mesh>
            <uri>package://spot_description/models/spot/meshes/rear_left_upper_leg_collision.stl</uri>
          </mesh>
        </geometry>
      </collision>
      <visual name="rear_left_upper_leg_visual">
        <geometry>
          <mesh>
            <uri>package://spot_description/models/spot/meshes/rear_left_upper_leg.dae</uri>
          </mesh>
        </geometry>
      </visual>
    </link>
    <joint name="rear_left_hip_y" type="revolute">
      <child>rear_left_upper_leg</child>
      <parent>rear_left_hip</parent>
      <axis>
        <xyz>0 1 0</xyz>
        <limit>
          <lower>-0.898845</lower>
          <upper>2.29511</upper>
          <effort>80</effort>
          <velocity>15</velocity>
        </limit>
        <dynamics>
          <spring_reference>0</spring_reference>
          <spring_stiffness>0</spring_stiffness>
        </dynamics>
      </axis>
    </joint>
    <link name="rear_left_lower_leg">
      <pose>-0.27285 0.165945 -0.3205 0 -0 0</pose>
      <inertial>
        <pose>0 0 -0.16 0 -0 0</pose>
        <mass>0.5</mass>
        <inertia>
          <ixx>0.00743438</ixx>
          <ixy>0</ixy>
          <ixz>0</ixz>
          <iyy>0.00740104</iyy>
          <iyz>0</iyz>
          <izz>0.000135417</izz>
        </inertia>
      </inertial>
      <collision name="rear_left_lower_leg_collision">
        <geometry>
          <mesh>
            <scale>0.82 0.97 0.98</scale>
            <uri>package://spot_description/models/spot/meshes/rear_left_lower_leg_collision.stl</uri>
          </mesh>
        </geometry>
        <surface>
          <contact>
            <ode>
              <kp>1e+07</kp>
              <kd>100</kd>
            </ode>
          </contact>
          <friction>
            <ode>
              <mu>0.8</mu>
              <mu2>0.8</mu2>
            </ode>
          </friction>
        </surface>
      </collision>
      <collision name="rear_left_lower_leg_collision_1">
        <pose>0 0 -0.333 0 -0 0</pose>
        <geometry>
          <sphere>
            <radius>0.04</radius>
          </sphere>
        </geometry>
        <surface>
          <contact>
            <ode>
              <kp>1e+07</kp>
              <kd>100</kd>
            </ode>
          </contact>
          <friction>
            <ode>
              <mu>0.8</mu>
              <mu2>0.8</mu2>
            </ode>
          </friction>
        </surface>
      </collision>
      <visual name="rear_left_lower_leg_visual">
        <geometry>
          <mesh>
            <uri>package://spot_description/models/spot/meshes/rear_left_lower_leg.dae</uri>
          </mesh>
        </geometry>
        <material>
        </material>
      </visual>
      <sensor name="contact" type="contact">
        <contact>
          <collision>rear_left_lower_leg_collision</collision>
          <collision>rear_left_lower_leg_collision_1</collision>
          <topic>__default_topic__</topic>
        </contact>
      </sensor>
    </link>
    <joint name="rear_left_knee" type="revolute">
      <child>rear_left_lower_leg</child>
      <parent>rear_left_upper_leg</parent>
      <axis>
        <xyz>0 1 0</xyz>
        <limit>
          <lower>-2.7929</lower>
          <upper>-0.254801</upper>
          <effort>80</effort>
          <velocity>15</velocity>
        </limit>
        <dynamics>
          <spring_reference>0</spring_reference>
          <spring_stiffness>0</spring_stiffness>
        </dynamics>
      </axis>
    </joint>
    <link name="rear_left_ee">
      <pose>-0.27285 0.165945 -0.6905 0 -0 0</pose>
      <inertial>
        <mass>1e-05</mass>
        <inertia>
          <ixx>0.001</ixx>
          <ixy>1e-06</ixy>
          <ixz>1e-06</ixz>
          <iyy>0.001</iyy>
          <iyz>1e-06</iyz>
          <izz>0.001</izz>
        </inertia>
      </inertial>
    </link>
    <joint name="rear_left_foot" type="fixed">
      <child>rear_left_ee</child>
      <parent>rear_left_lower_leg</parent>
      <axis>
        <dynamics>
          <spring_reference>0</spring_reference>
          <spring_stiffness>0</spring_stiffness>
        </dynamics>
        <xyz>0 0 1</xyz>
        <limit>
          <lower>-1e+16</lower>
          <upper>1e+16</upper>
        </limit>
      </axis>
      <physics>
        <ode>
          <limit>
            <cfm>0</cfm>
            <erp>0.2</erp>
          </limit>
        </ode>
      </physics>
    </joint>
    <link name="rear_right_hip">
      <pose>-0.29785 -0.055 0 0 -0 0</pose>
      <inertial>
        <mass>2</mass>
        <inertia>
          <ixx>0.0027</ixx>
          <ixy>0</ixy>
          <ixz>0</ixz>
          <iyy>0.00416667</iyy>
          <iyz>0</iyz>
          <izz>0.00416667</izz>
        </inertia>
      </inertial>
      <collision name="rear_right_hip_collision">
        <geometry>
          <mesh>
            <uri>package://spot_description/models/spot/meshes/rear_right_hip_collision.stl</uri>
          </mesh>
        </geometry>
      </collision>
      <visual name="rear_right_hip_visual">
        <geometry>
          <mesh>
            <uri>package://spot_description/models/spot/meshes/rear_right_hip.dae</uri>
          </mesh>
        </geometry>
      </visual>
    </link>
    <joint name="rear_right_hip_x" type="revolute">
      <child>rear_right_hip</child>
      <parent>base_link</parent>
      <axis>
        <xyz>1 0 0</xyz>
        <limit>
          <lower>-0.785398</lower>
          <upper>0.785398</upper>
          <effort>80</effort>
          <velocity>15</velocity>
        </limit>
        <dynamics>
          <spring_reference>0</spring_reference>
          <spring_stiffness>0</spring_stiffness>
        </dynamics>
      </axis>
    </joint>
    <link name="rear_right_upper_leg">
      <pose>-0.29785 -0.165945 0 0 -0 0</pose>
      <inertial>
        <pose>0 0 -0.14 0 -0 0</pose>
        <mass>1</mass>
        <inertia>
          <ixx>0.0155334</ixx>
          <ixy>0</ixy>
          <ixz>0</ixz>
          <iyy>0.0155334</iyy>
          <iyz>0</iyz>
          <izz>0.000962667</izz>
        </inertia>
      </inertial>
      <collision name="rear_right_upper_leg_collision">
        <geometry>
          <mesh>
            <uri>package://spot_description/models/spot/meshes/rear_right_upper_leg_collision.stl</uri>
          </mesh>
        </geometry>
      </collision>
      <visual name="rear_right_upper_leg_visual">
        <geometry>
          <mesh>
            <uri>package://spot_description/models/spot/meshes/rear_right_upper_leg.dae</uri>
          </mesh>
        </geometry>
      </visual>
    </link>
    <joint name="rear_right_hip_y" type="revolute">
      <child>rear_right_upper_leg</child>
      <parent>rear_right_hip</parent>
      <axis>
        <xyz>0 1 0</xyz>
        <limit>
          <lower>-0.898845</lower>
          <upper>2.29511</upper>
          <effort>80</effort>
          <velocity>15</velocity>
        </limit>
        <dynamics>
          <spring_reference>0</spring_reference>
          <spring_stiffness>0</spring_stiffness>
        </dynamics>
      </axis>
    </joint>
    <link name="rear_right_lower_leg">
      <pose>-0.27285 -0.165945 -0.3205 0 -0 0</pose>
      <inertial>
        <pose>0 0 -0.16 0 -0 0</pose>
        <mass>0.5</mass>
        <inertia>
          <ixx>0.00743438</ixx>
          <ixy>0</ixy>
          <ixz>0</ixz>
          <iyy>0.00740104</iyy>
          <iyz>0</iyz>
          <izz>0.000135417</izz>
        </inertia>
      </inertial>
      <collision name="rear_right_lower_leg_collision">
        <geometry>
          <mesh>
            <scale>0.82 0.97 0.98</scale>
            <uri>package://spot_description/models/spot/meshes/rear_right_lower_leg_collision.stl</uri>
          </mesh>
        </geometry>
        <surface>
          <contact>
            <ode>
              <kp>1e+07</kp>
              <kd>100</kd>
            </ode>
          </contact>
          <friction>
            <ode>
              <mu>0.8</mu>
              <mu2>0.8</mu2>
            </ode>
          </friction>
        </surface>
      </collision>
      <collision name="rear_right_lower_leg_collision_1">
        <pose>0 0 -0.333 0 -0 0</pose>
        <geometry>
          <sphere>
            <radius>0.04</radius>
          </sphere>
        </geometry>
        <surface>
          <contact>
            <ode>
              <kp>1e+07</kp>
              <kd>100</kd>
            </ode>
          </contact>
          <friction>
            <ode>
              <mu>0.8</mu>
              <mu2>0.8</mu2>
            </ode>
          </friction>
        </surface>
      </collision>
      <visual name="rear_right_lower_leg_visual">
        <geometry>
          <mesh>
            <uri>package://spot_description/models/spot/meshes/rear_right_lower_leg.dae</uri>
          </mesh>
        </geometry>
        <material>
        </material>
      </visual>
      <sensor name="contact" type="contact">
        <contact>
          <collision>rear_right_lower_leg_collision</collision>
          <collision>rear_right_lower_leg_collision_1</collision>
          <topic>__default_topic__</topic>
        </contact>
      </sensor>
    </link>
    <joint name="rear_right_knee" type="revolute">
      <child>rear_right_lower_leg</child>
      <parent>rear_right_upper_leg</parent>
      <axis>
        <xyz>0 1 0</xyz>
        <limit>
          <lower>-2.7929</lower>
          <upper>-0.254801</upper>
          <effort>80</effort>
          <velocity>15</velocity>
        </limit>
        <dynamics>
          <spring_reference>0</spring_reference>
          <spring_stiffness>0</spring_stiffness>
        </dynamics>
      </axis>
    </joint>
    <link name="rear_right_ee">
      <pose>-0.27285 -0.165945 -0.6905 0 -0 0</pose>
      <inertial>
        <mass>1e-05</mass>
        <inertia>
          <ixx>0.001</ixx>
          <ixy>1e-06</ixy>
          <ixz>1e-06</ixz>
          <iyy>0.001</iyy>
          <iyz>1e-06</iyz>
          <izz>0.001</izz>
        </inertia>
      </inertial>
    </link>
    <joint name="rear_right_foot" type="fixed">
      <child>rear_right_ee</child>
      <parent>rear_right_lower_leg</parent>
      <axis>
        <dynamics>
          <spring_reference>0</spring_reference>
          <spring_stiffness>0</spring_stiffness>
        </dynamics>
        <xyz>0 0 1</xyz>
        <limit>
          <lower>-1e+16</lower>
          <upper>1e+16</upper>
        </limit>
      </axis>
      <physics>
        <ode>
          <limit>
            <cfm>0</cfm>
            <erp>0.2</erp>
          </limit>
        </ode>
      </physics>
    </joint>

    <plugin
      filename="gz-sim-joint-state-publisher-system"
      name="gz::sim::systems::JointStatePublisher">
      <topic>model/spot/joint_state</topic>
    </plugin>

    <plugin
      filename="gz-sim-odometry-publisher-system"
      name="gz::sim::systems::OdometryPublisher">
      <odom_frame>odom</odom_frame>
      <robot_base_frame>base_link</robot_base_frame>
      <dimensions>3</dimensions>
    </plugin>

    <plugin
      filename="gz-sim-joint-trajectory-controller-system"
      name="gz::sim::systems::JointTrajectoryController">
      <topic>model/spot/joint_trajectory</topic>

      <joint_name>front_left_hip_x</joint_name>
      <position_p_gain>500</position_p_gain>
      <position_i_gain>1</position_i_gain>
      <position_d_gain>20</position_d_gain>

      <joint_name>front_left_hip_y</joint_name>
      <position_p_gain>500</position_p_gain>
      <position_i_gain>1</position_i_gain>
      <position_d_gain>20</position_d_gain>

      <joint_name>front_left_knee</joint_name>
      <position_p_gain>500</position_p_gain>
      <position_i_gain>1</position_i_gain>
      <position_d_gain>20</position_d_gain>

      <joint_name>front_right_hip_x</joint_name>
      <position_p_gain>500</position_p_gain>
      <position_i_gain>1</position_i_gain>
      <position_d_gain>20</position_d_gain>

      <joint_name>front_right_hip_y</joint_name>
      <position_p_gain>500</position_p_gain>
      <position_i_gain>1</position_i_gain>
      <position_d_gain>20</position_d_gain>

      <joint_name>front_right_knee</joint_name>
      <position_p_gain>500</position_p_gain>
      <position_i_gain>1</position_i_gain>
      <position_d_gain>20</position_d_gain>

      <joint_name>rear_left_hip_x</joint_name>
      <position_p_gain>500</position_p_gain>
      <position_i_gain>1</position_i_gain>
      <position_d_gain>20</position_d_gain>

      <joint_name>rear_left_hip_y</joint_name>
      <position_p_gain>500</position_p_gain>
      <position_i_gain>1</position_i_gain>
      <position_d_gain>20</position_d_gain>

      <joint_name>rear_left_knee</joint_name>
      <position_p_gain>500</position_p_gain>
      <position_i_gain>1</position_i_gain>
      <position_d_gain>20</position_d_gain>

      <joint_name>rear_right_hip_x</joint_name>
      <position_p_gain>500</position_p_gain>
      <position_i_gain>1</position_i_gain>
      <position_d_gain>20</position_d_gain>

      <joint_name>rear_right_hip_y</joint_name>
      <position_p_gain>500</position_p_gain>
      <position_i_gain>1</position_i_gain>
      <position_d_gain>20</position_d_gain>

      <joint_name>rear_right_knee</joint_name>
      <position_p_gain>500</position_p_gain>
      <position_i_gain>1</position_i_gain>
      <position_d_gain>20</position_d_gain>
    </plugin>

  </model>
</sdf>